<mujoco>
    <compiler coordinate="local" angle="radian" meshdir="meshes" strippath="false" />
    <option timestep="0.008" iterations="40" solver="CG" tolerance="1e-10" />
    <default>
        <default class="wheel">
            <joint axis="0 0 -1" damping=".3" />
            <motor ctrlrange="-100 100" gear="1" forcerange="-100 100" />
        </default>
    </default>
    <visual>
        <rgba haze=".3 .3 .3 1" />
    </visual>

    <asset>
        <texture type="2d" name="edie8_face" file="meshes/visual/edie8_face.png" gridsize="1 1" />
        <material name="edie8_face" texture="edie8_face" texrepeat="1 1" texuniform="false" />
    </asset>

    <worldbody>

        <body name="body" pos="0 0 0.2">
            <body name="main_body" pos="0 0 0.05">
                <geom type="sphere" size="0.05" mass="0.0001" />
                <site name="imu" size="0.01" pos="0 0 0.0" />
            </body>

            <freejoint />
            <body name="l_leg" pos="0 0.045 -0.02" euler="-3.141592 0 0">
                <body name="l_wheel" pos="0 -0.005 0.06" euler="1.570796 0 0">
                    <geom type="cylinder" size="0.06 0.04" mass="5.0" />
                    <joint name="joint_left_wheel" class="wheel" />
                </body>
            </body>
            <body
                name="r_leg" pos="0 -0.045 -0.02" euler="-3.141592 0 3.141592">
                <body name="r_wheel" pos="0 -0.005 0.06" euler="-1.570796 0 0">
                    <geom type="cylinder" size="0.06 0.04" mass="5.0" />
                    <joint name="joint_right_wheel" class="wheel" />
                </body>
            </body>
            <body
                name="face" pos="0.055 0 0.09" euler="0.0 0.872665 0">
                <geom type="cylinder" size="0.065 0.01" mass="0" material="edie8_face" />
            </body>
        </body>

    </worldbody>

    <contact>
        <exclude body1="l_wheel" body2="l_leg" />
        <exclude body1="r_wheel" body2="r_leg" />
    </contact>

    <tendon>
        <fixed name="forward">
            <joint joint="joint_left_wheel" coef=".5" />
            <joint joint="joint_right_wheel" coef=".5" />
        </fixed>
        <fixed name="turn">
            <joint joint="joint_left_wheel" coef="-.5" />
            <joint joint="joint_right_wheel" coef=".5" />
        </fixed>
    </tendon>

    <actuator>
        <motor name="forward" tendon="forward" class="wheel" />
        <motor name="turn" tendon="turn" class="wheel" />
    </actuator>


    <sensor>
        <gyro name="angular_velocity" site="imu" noise="5e-4" cutoff="34.9" />
        <accelerometer name="linear_acceleration" site="imu" noise="1e-2" cutoff="157" />
        <jointvel name="jointvel_l" joint="joint_left_wheel" />
        <jointvel name="jointvel_r" joint="joint_right_wheel" />
    </sensor>

    <sensor>
        <framepos name="framepos_body_main" objtype="body" objname="main_body" />
        <framequat name="framexaxis_body_main" objtype="body" objname="main_body" />
        <framexaxis name="framexaxis" objtype="body" objname="main_body" />
    </sensor>
</mujoco>